{
    "registryname": "evilblood_altar",
    "localizedname": "邪恶血液祭坛",
    "color":"404040",
    "parts": [
        {
            "x": -5,
            "y": -2,
            "z": 3,
            "elements": [
                "bloodmagic:blood_rune@0"
            ]
        },
        {
            "x": -1,
            "y": 0,
            "z": 0,
            "elements": [
                "bloodmagic:blood_rune@0"
            ]
        },
        {
            "x": 1,
            "y": 0,
            "z": 0,
            "elements": [
                "bloodmagic:blood_rune@0"
            ]
        },
        {
            "x": -5,
            "y": -2,
            "z": -1,
            "elements": [
                "bloodmagic:blood_rune@0"
            ]
        },
        {
            "x": 5,
            "y": -2,
            "z": 3,
            "elements": [
                "bloodmagic:blood_rune@0"
            ]
        },
        {
            "x": 8,
            "y": -3,
            "z": -1,
            "elements": [
                "bloodmagic:blood_rune@0"
            ]
        },
        {
            "x": 8,
            "y": -3,
            "z": -5,
            "elements": [
                "bloodmagic:blood_rune@0"
            ]
        },
        {
            "x": 3,
            "y": -1,
            "z": 0,
            "elements": [
                "bloodmagic:blood_rune@0"
            ]
        },
        {
            "x": -8,
            "y": -3,
            "z": 2,
            "elements": [
                "bloodmagic:blood_rune@0"
            ]
        },
        {
            "x": -3,
            "y": -1,
            "z": 0,
            "elements": [
                "bloodmagic:blood_rune@0"
            ]
        },
        {
            "x": -3,
            "y": -1,
            "z": 3,
            "elements": [
                "bloodmagic:blood_rune@0"
            ]
        },
        {
            "x": -8,
            "y": -3,
            "z": 6,
            "elements": [
                "bloodmagic:blood_rune@0"
            ]
        },
        {
            "x": -8,
            "y": -3,
            "z": -1,
            "elements": [
                "bloodmagic:blood_rune@0"
            ]
        },
        {
            "x": 3,
            "y": -1,
            "z": 3,
            "elements": [
                "bloodmagic:blood_rune@0"
            ]
        },
        {
            "x": -8,
            "y": -3,
            "z": -5,
            "elements": [
                "bloodmagic:blood_rune@0"
            ]
        },
        {
            "x": 8,
            "y": -3,
            "z": 2,
            "elements": [
                "bloodmagic:blood_rune@0"
            ]
        },
        {
            "x": 8,
            "y": -3,
            "z": 6,
            "elements": [
                "bloodmagic:blood_rune@0"
            ]
        },
        {
            "x": 5,
            "y": -2,
            "z": 0,
            "elements": [
                "bloodmagic:blood_rune@0"
            ]
        },
        {
            "x": 3,
            "y": -2,
            "z": -4,
            "elements": [
                "bloodmagic:blood_rune@0"
            ]
        },
        {
            "x": -5,
            "y": -2,
            "z": 2,
            "elements": [
                "bloodmagic:blood_rune@0"
            ]
        },
        {
            "x": -3,
            "y": 2,
            "z": 4,
            "elements": [
                "minecraft:glowstone@0"
            ]
        },
        {
            "x": 2,
            "y": -2,
            "z": -4,
            "elements": [
                "bloodmagic:blood_rune@0"
            ]
        },
        {
            "x": 3,
            "y": 2,
            "z": -2,
            "elements": [
                "minecraft:glowstone@0"
            ]
        },
        {
            "x": 1,
            "y": -2,
            "z": -4,
            "elements": [
                "bloodmagic:blood_rune@0"
            ]
        },
        {
            "x": 0,
            "y": -2,
            "z": -4,
            "elements": [
                "bloodmagic:blood_rune@0"
            ]
        },
        {
            "x": -5,
            "y": -2,
            "z": 0,
            "elements": [
                "bloodmagic:blood_rune@0"
            ]
        },
        {
            "x": -1,
            "y": -2,
            "z": -4,
            "elements": [
                "bloodmagic:blood_rune@0"
            ]
        },
        {
            "x": -2,
            "y": -2,
            "z": -4,
            "elements": [
                "bloodmagic:blood_rune@0"
            ]
        },
        {
            "x": -3,
            "y": -2,
            "z": -4,
            "elements": [
                "bloodmagic:blood_rune@0"
            ]
        },
        {
            "x": 3,
            "y": 2,
            "z": 4,
            "elements": [
                "minecraft:glowstone@0"
            ]
        },
        {
            "x": -3,
            "y": -2,
            "z": 6,
            "elements": [
                "bloodmagic:blood_rune@0"
            ]
        },
        {
            "x": -3,
            "y": 2,
            "z": -2,
            "elements": [
                "minecraft:glowstone@0"
            ]
        },
        {
            "x": -2,
            "y": -2,
            "z": 6,
            "elements": [
                "bloodmagic:blood_rune@0"
            ]
        },
        {
            "x": -1,
            "y": -2,
            "z": 6,
            "elements": [
                "bloodmagic:blood_rune@0"
            ]
        },
        {
            "x": 0,
            "y": -2,
            "z": 6,
            "elements": [
                "bloodmagic:blood_rune@0"
            ]
        },
        {
            "x": 1,
            "y": -2,
            "z": 6,
            "elements": [
                "bloodmagic:blood_rune@0"
            ]
        },
        {
            "x": 5,
            "y": -2,
            "z": 2,
            "elements": [
                "bloodmagic:blood_rune@0"
            ]
        },
        {
            "x": 2,
            "y": -2,
            "z": 6,
            "elements": [
                "bloodmagic:blood_rune@0"
            ]
        },
        {
            "x": 3,
            "y": -2,
            "z": 6,
            "elements": [
                "bloodmagic:blood_rune@0"
            ]
        },
        {
            "x": 8,
            "y": -3,
            "z": 0,
            "elements": [
                "bloodmagic:blood_rune@0"
            ]
        },
        {
            "x": 8,
            "y": -3,
            "z": -4,
            "elements": [
                "bloodmagic:blood_rune@0"
            ]
        },
        {
            "x": -8,
            "y": -3,
            "z": 1,
            "elements": [
                "bloodmagic:blood_rune@0"
            ]
        },
        {
            "x": -3,
            "y": -1,
            "z": 2,
            "elements": [
                "bloodmagic:blood_rune@0"
            ]
        },
        {
            "x": -8,
            "y": -3,
            "z": 5,
            "elements": [
                "bloodmagic:blood_rune@0"
            ]
        },
        {
            "x": -8,
            "y": -3,
            "z": 0,
            "elements": [
                "bloodmagic:blood_rune@0"
            ]
        },
        {
            "x": 3,
            "y": -1,
            "z": 2,
            "elements": [
                "bloodmagic:blood_rune@0"
            ]
        },
        {
            "x": -6,
            "y": -3,
            "z": 9,
            "elements": [
                "bloodmagic:blood_rune@0"
            ]
        },
        {
            "x": -5,
            "y": -3,
            "z": 9,
            "elements": [
                "bloodmagic:blood_rune@0"
            ]
        },
        {
            "x": -8,
            "y": -3,
            "z": -4,
            "elements": [
                "bloodmagic:blood_rune@0"
            ]
        },
        {
            "x": -4,
            "y": -3,
            "z": 9,
            "elements": [
                "bloodmagic:blood_rune@0"
            ]
        },
        {
            "x": -3,
            "y": -3,
            "z": 9,
            "elements": [
                "bloodmagic:blood_rune@0"
            ]
        },
        {
            "x": -2,
            "y": -3,
            "z": 9,
            "elements": [
                "bloodmagic:blood_rune@0"
            ]
        },
        {
            "x": -1,
            "y": -3,
            "z": 9,
            "elements": [
                "bloodmagic:blood_rune@0"
            ]
        },
        {
            "x": 0,
            "y": -3,
            "z": 9,
            "elements": [
                "bloodmagic:blood_rune@0"
            ]
        },
        {
            "x": 8,
            "y": -3,
            "z": 1,
            "elements": [
                "bloodmagic:blood_rune@0"
            ]
        },
        {
            "x": 1,
            "y": -3,
            "z": 9,
            "elements": [
                "bloodmagic:blood_rune@0"
            ]
        },
        {
            "x": 2,
            "y": -3,
            "z": 9,
            "elements": [
                "bloodmagic:blood_rune@0"
            ]
        },
        {
            "x": 3,
            "y": -3,
            "z": 9,
            "elements": [
                "bloodmagic:blood_rune@0"
            ]
        },
        {
            "x": 4,
            "y": -3,
            "z": 9,
            "elements": [
                "bloodmagic:blood_rune@0"
            ]
        },
        {
            "x": 8,
            "y": -3,
            "z": 5,
            "elements": [
                "bloodmagic:blood_rune@0"
            ]
        },
        {
            "x": 5,
            "y": -3,
            "z": 9,
            "elements": [
                "bloodmagic:blood_rune@0"
            ]
        },
        {
            "x": 6,
            "y": -3,
            "z": 9,
            "elements": [
                "bloodmagic:blood_rune@0"
            ]
        },
        {
            "x": 8,
            "y": -2,
            "z": -7,
            "elements": [
                "minecraft:beacon@0"
            ]
        },
        {
            "x": -5,
            "y": -2,
            "z": 1,
            "elements": [
                "bloodmagic:blood_rune@0"
            ]
        },
        {
            "x": -1,
            "y": 0,
            "z": 2,
            "elements": [
                "bloodmagic:blood_rune@0"
            ]
        },
        {
            "x": 0,
            "y": 0,
            "z": 2,
            "elements": [
                "bloodmagic:blood_rune@0"
            ]
        },
        {
            "x": -8,
            "y": -2,
            "z": 9,
            "elements": [
                "minecraft:beacon@0"
            ]
        },
        {
            "x": 1,
            "y": 0,
            "z": 2,
            "elements": [
                "bloodmagic:blood_rune@0"
            ]
        },
        {
            "x": 5,
            "y": -2,
            "z": 1,
            "elements": [
                "bloodmagic:blood_rune@0"
            ]
        },
        {
            "x": -8,
            "y": -2,
            "z": -7,
            "elements": [
                "minecraft:beacon@0"
            ]
        },
        {
            "x": 8,
            "y": -2,
            "z": 9,
            "elements": [
                "minecraft:beacon@0"
            ]
        },
        {
            "x": 8,
            "y": -3,
            "z": -3,
            "elements": [
                "bloodmagic:blood_rune@0"
            ]
        },
        {
            "x": 6,
            "y": -3,
            "z": -7,
            "elements": [
                "bloodmagic:blood_rune@0"
            ]
        },
        {
            "x": 2,
            "y": -1,
            "z": -2,
            "elements": [
                "bloodmagic:blood_rune@0"
            ]
        },
        {
            "x": 5,
            "y": -3,
            "z": -7,
            "elements": [
                "bloodmagic:blood_rune@0"
            ]
        },
        {
            "x": -3,
            "y": -1,
            "z": 1,
            "elements": [
                "bloodmagic:blood_rune@0"
            ]
        },
        {
            "x": -8,
            "y": -3,
            "z": 4,
            "elements": [
                "bloodmagic:blood_rune@0"
            ]
        },
        {
            "x": 1,
            "y": -1,
            "z": -2,
            "elements": [
                "bloodmagic:blood_rune@0"
            ]
        },
        {
            "x": 4,
            "y": -3,
            "z": -7,
            "elements": [
                "bloodmagic:blood_rune@0"
            ]
        },
        {
            "x": 0,
            "y": -1,
            "z": -2,
            "elements": [
                "bloodmagic:blood_rune@0"
            ]
        },
        {
            "x": 3,
            "y": -3,
            "z": -7,
            "elements": [
                "bloodmagic:blood_rune@0"
            ]
        },
        {
            "x": 5,
            "y": 3,
            "z": -4,
            "elements": [
                "bloodmagic:decorative_brick@1"
            ]
        },
        {
            "x": 2,
            "y": -3,
            "z": -7,
            "elements": [
                "bloodmagic:blood_rune@0"
            ]
        },
        {
            "x": -1,
            "y": -1,
            "z": -2,
            "elements": [
                "bloodmagic:blood_rune@0"
            ]
        },
        {
            "x": 1,
            "y": -3,
            "z": -7,
            "elements": [
                "bloodmagic:blood_rune@0"
            ]
        },
        {
            "x": -2,
            "y": -1,
            "z": -2,
            "elements": [
                "bloodmagic:blood_rune@0"
            ]
        },
        {
            "x": 0,
            "y": -3,
            "z": -7,
            "elements": [
                "bloodmagic:blood_rune@0"
            ]
        },
        {
            "x": -1,
            "y": -3,
            "z": -7,
            "elements": [
                "bloodmagic:blood_rune@0"
            ]
        },
        {
            "x": 3,
            "y": -1,
            "z": 1,
            "elements": [
                "bloodmagic:blood_rune@0"
            ]
        },
        {
            "x": -2,
            "y": -3,
            "z": -7,
            "elements": [
                "bloodmagic:blood_rune@0"
            ]
        },
        {
            "x": -3,
            "y": -3,
            "z": -7,
            "elements": [
                "bloodmagic:blood_rune@0"
            ]
        },
        {
            "x": -4,
            "y": -3,
            "z": -7,
            "elements": [
                "bloodmagic:blood_rune@0"
            ]
        },
        {
            "x": -8,
            "y": -3,
            "z": -3,
            "elements": [
                "bloodmagic:blood_rune@0"
            ]
        },
        {
            "x": -5,
            "y": -3,
            "z": -7,
            "elements": [
                "bloodmagic:blood_rune@0"
            ]
        },
        {
            "x": -6,
            "y": -3,
            "z": -7,
            "elements": [
                "bloodmagic:blood_rune@0"
            ]
        },
        {
            "x": -5,
            "y": 3,
            "z": -4,
            "elements": [
                "bloodmagic:decorative_brick@1"
            ]
        },
        {
            "x": 8,
            "y": -3,
            "z": 4,
            "elements": [
                "bloodmagic:blood_rune@0"
            ]
        },
        {
            "x": 5,
            "y": -2,
            "z": -2,
            "elements": [
                "bloodmagic:blood_rune@0"
            ]
        },
        {
            "x": -1,
            "y": 0,
            "z": 1,
            "elements": [
                "modularmachinery:blockoutputbus@2"
            ]
        },
        {
            "x": 0,
            "y": 0,
            "z": 1,
            "elements": [
                "modularmachinery:blockfluidinputhatch@4"
            ]
        },
        {
            "x": -5,
            "y": -2,
            "z": 4,
            "elements": [
                "bloodmagic:blood_rune@0"
            ]
        },
        {
            "x": 1,
            "y": 0,
            "z": 1,
            "elements": [
                "modularmachinery:blockinputbus@2"
            ]
        },
        {
            "x": -5,
            "y": -2,
            "z": -2,
            "elements": [
                "bloodmagic:blood_rune@0"
            ]
        },
        {
            "x": 5,
            "y": -2,
            "z": 4,
            "elements": [
                "bloodmagic:blood_rune@0"
            ]
        },
        {
            "x": 8,
            "y": -3,
            "z": -2,
            "elements": [
                "bloodmagic:blood_rune@0"
            ]
        },
        {
            "x": 3,
            "y": -1,
            "z": -1,
            "elements": [
                "bloodmagic:blood_rune@0"
            ]
        },
        {
            "x": -8,
            "y": -3,
            "z": 3,
            "elements": [
                "bloodmagic:blood_rune@0"
            ]
        },
        {
            "x": -5,
            "y": 3,
            "z": 6,
            "elements": [
                "bloodmagic:decorative_brick@1"
            ]
        },
        {
            "x": 0,
            "y": 1,
            "z": 1,
            "elements": [
                "evilcraft:sanguinary_pedestal@1"
            ]
        },
        {
            "x": -3,
            "y": -1,
            "z": -1,
            "elements": [
                "bloodmagic:blood_rune@0"
            ]
        },
        {
            "x": -8,
            "y": -3,
            "z": 7,
            "elements": [
                "bloodmagic:blood_rune@0"
            ]
        },
        {
            "x": -2,
            "y": -1,
            "z": 4,
            "elements": [
                "bloodmagic:blood_rune@0"
            ]
        },
        {
            "x": -1,
            "y": -1,
            "z": 4,
            "elements": [
                "bloodmagic:blood_rune@0"
            ]
        },
        {
            "x": 0,
            "y": -1,
            "z": 4,
            "elements": [
                "bloodmagic:blood_rune@0"
            ]
        },
        {
            "x": -8,
            "y": -3,
            "z": -2,
            "elements": [
                "bloodmagic:blood_rune@0"
            ]
        },
        {
            "x": 1,
            "y": -1,
            "z": 4,
            "elements": [
                "bloodmagic:blood_rune@0"
            ]
        },
        {
            "x": 2,
            "y": -1,
            "z": 4,
            "elements": [
                "bloodmagic:blood_rune@0"
            ]
        },
        {
            "x": 5,
            "y": 3,
            "z": 6,
            "elements": [
                "bloodmagic:decorative_brick@1"
            ]
        },
        {
            "x": 8,
            "y": -3,
            "z": 3,
            "elements": [
                "bloodmagic:blood_rune@0"
            ]
        },
        {
            "x": 8,
            "y": -3,
            "z": 7,
            "elements": [
                "bloodmagic:blood_rune@0"
            ]
        },
        {
            "x": 5,
            "y": -2,
            "z": -1,
            "elements": [
                "bloodmagic:blood_rune@0"
            ]
        }
    ]}